Workbook

Sheet AWS1_30min
G1: Вт/м2 | H1: Вт/м2 | I1: Альбедо | J1: Вт/м2 | K1: Вт/м2 | L1: °C | M1: % | N1: м/с | O1: гПа | P1: мм/30 мин
D2: Ячейка | E2: Ячейка | F2: Ячейка | G2: meas Lpnet | H2: meas Lpnet | I2: расчет | J2: meas Lpnet | K2: meas Lpnet | L2: meas | M2: meas | N2: meas | O2: meas | P2: meas
A3: Дата | B3: Время | C3: Дата&Время | D3: X | E3: Y | F3: Z | G3: Sin | H3: Sout | I3: α | J3: Lin | K3: Lout | L3: T2m | M3: RH2m | N3: WS2m | O3: p | P3: Prec
A4: 43651 | B4: 0.83333333 | C4: =A4+B4 -> 43651.833 | D4: 525465 | E4: 6300495 | F4: 2536 | G4: NODATA | H4: NODATA | I4: NODATA | J4: NODATA | K4: NODATA | L4: 7.37 | M4: 65.397 | N4: 2.998 | O4: 747.83 | P4: 0.2
A5: 43651 | B5: 0.85416667 | C5: =A5+B5 -> 43651.854 | D5: =D4 -> 525465 | E5: =E4 -> 6300495 | F5: =F4 -> 2536 | G5: NODATA | H5: NODATA | I5: NODATA | J5: NODATA | K5: NODATA | L5: 7.433 | M5: 64.775 | N5: 3.732 | O5: 748.027 | P5: 0
A6: 43651 | B6: 0.875 | C6: =A6+B6 -> 43651.875 | D6: =D5 -> 525465 | E6: =E5 -> 6300495 | F6: =F5 -> 2536 | G6: NODATA | H6: NODATA | I6: NODATA | J6: NODATA | K6: NODATA | L6: 7.182 | M6: 66.63 | N6: 3.046 | O6: 747.96 | P6: 0
A7: 43651 | B7: 0.89583333 | C7: =A7+B7 -> 43651.896 | D7: =D6 -> 525465 | E7: =E6 -> 6300495 | F7: =F6 -> 2536 | G7: NODATA | H7: NODATA | I7: NODATA | J7: NODATA | K7: NODATA | L7: 7.37 | M7: 66.184 | N7: 3.266 | O7: 748.44 | P7: 0
A8: 43651 | B8: 0.91666667 | C8: =A8+B8 -> 43651.917 | D8: =D7 -> 525465 | E8: =E7 -> 6300495 | F8: =F7 -> 2536 | G8: NODATA | H8: NODATA | I8: NODATA | J8: NODATA | K8: NODATA | L8: 7.37 | M8: 67.128 | N8: 3.128 | O8: 748.508 | P8: 0
A9: 43651 | B9: 0.9375 | C9: =A9+B9 -> 43651.938 | D9: =D8 -> 525465 | E9: =E8 -> 6300495 | F9: =F8 -> 2536 | G9: NODATA | H9: NODATA | I9: NODATA | J9: NODATA | K9: NODATA | L9: 7.496 | M9: 67.303 | N9: 3.011 | O9: 748.292 | P9: 0
A10: 43651 | B10: 0.95833333 | C10: =A10+B10 -> 43651.958 | D10: =D9 -> 525465 | E10: =E9 -> 6300495 | F10: =F9 -> 2536 | G10: NODATA | H10: NODATA | I10: NODATA | J10: NODATA | K10: NODATA | L10: 7.622 | M10: 66.376 | N10: 3.267 | O10: 748.185 | P10: 0
A11: 43651 | B11: 0.97916667 | C11: =A11+B11 -> 43651.979 | D11: =D10 -> 525465 | E11: =E10 -> 6300495 | F11: =F10 -> 2536 | G11: NODATA | H11: NODATA | I11: NODATA | J11: NODATA | K11: NODATA | L11: 7.559 | M11: 66.21 | N11: 4.89 | O11: 748 | P11: 0
A12: 43652 | B12: 0 | C12: =A12+B12 -> 43652 | D12: =D11 -> 525465 | E12: =E11 -> 6300495 | F12: =F11 -> 2536 | G12: NODATA | H12: NODATA | I12: NODATA | J12: NODATA | K12: NODATA | L12: 7.244 | M12: 66.953 | N12: 3.455 | O12: 748.26 | P12: 0
A13: 43652 | B13: 0.020833333 | C13: =A13+B13 -> 43652.021 | D13: =D12 -> 525465 | E13: =E12 -> 6300495 | F13: =F12 -> 2536 | G13: NODATA | H13: NODATA | I13: NODATA | J13: NODATA | K13: NODATA | L13: 6.93 | M13: 68.482 | N13: 2.257 | O13: 748.19 | P13: 0
A14: 43652 | B14: 0.041666667 | C14: =A14+B14 -> 43652.042 | D14: =D13 -> 525465 | E14: =E13 -> 6300495 | F14: =F13 -> 2536 | G14: NODATA | H14: NODATA | I14: NODATA | J14: NODATA | K14: NODATA | L14: 7.622 | M14: 65.273 | N14: 2.532 | O14: 748.31 | P14: 0
A15: 43652 | B15: 0.0625 | C15: =A15+B15 -> 43652.062 | D15: =D14 -> 525465 | E15: =E14 -> 6300495 | F15: =F14 -> 2536 | G15: NODATA | H15: NODATA | I15: NODATA | J15: NODATA | K15: NODATA | L15: 7.433 | M15: 66.507 | N15: 1.622 | O15: 748.305 | P15: 0
A16: 43652 | B16: 0.083333333 | C16: =A16+B16 -> 43652.083 | D16: =D15 -> 525465 | E16: =E15 -> 6300495 | F16: =F15 -> 2536 | G16: NODATA | H16: NODATA | I16: NODATA | J16: NODATA | K16: NODATA | L16: 7.433 | M16: 66.507 | N16: 2.037 | O16: 748.18 | P16: 0
... A38: 43652 | B38: 0.54166667 | C38: =A38+B38 -> 43652.542 | D38: =D37 -> 525465 | E38: =E37 -> 6300495 | F38: =F37 -> 2536 | G38: NODATA | H38: NODATA | I38: NODATA | J38: NODATA | K38: NODATA | L38: 12.523 | M38: 36.546 | N38: 1.326 | O38: 750.063 | P38: 0
A39: 43652 | B39: 0.5625 | C39: =A39+B39 -> 43652.562 | D39: =D38 -> 525465 | E39: =E38 -> 6300495 | F39: =F38 -> 2536 | G39: 868.2 | H39: 106.3 | I39: 0.12243723 | J39: 276.52439 | K39: 454.15439 | L39: 12.9 | M39: 34.673 | N39: 0.001 | O39: 750.09 | P39: 0
A40: 43652 | B40: 0.58333333 | C40: =A40+B40 -> 43652.583 | D40: =D39 -> 525465 | E40: =E39 -> 6300495 | F40: =F39 -> 2536 | G40: 832.4 | H40: 99 | I40: 0.11893321 | J40: 276.37523 | K40: 456.99323 | L40: 13.151 | M40: 33.514 | N40: 1.363 | O40: 750.093 | P40: 0
A41: 43652 | B41: 0.60416667 | C41: =A41+B41 -> 43652.604 | D41: =D40 -> 525465 | E41: =E40 -> 6300495 | F41: =F40 -> 2536 | G41: 753.9 | H41: 90.9 | I41: 0.12057302 | J41: 277.44613 | K41: 460.58913 | L41: 13.653 | M41: 31.964 | N41: 1.125 | O41: 750.045 | P41: 0
A42: 43652 | B42: 0.625 | C42: =A42+B42 -> 43652.625 | D42: =D41 -> 525465 | E42: =E41 -> 6300495 | F42: =F41 -> 2536 | G42: 755.4 | H42: 93.2 | I42: 0.12337834 | J42: 278.51738 | K42: 458.52038 | L42: 13.841 | M42: 32.265 | N42: 1.282 | O42: 749.995 | P42: 0
A43: 43652 | B43: 0.64583333 | C43: =A43+B43 -> 43652.646 | D43: =D42 -> 525465 | E43: =E42 -> 6300495 | F43: =F42 -> 2536 | G43: 416 | H43: 51.3 | I43: 0.12331731 | J43: 281.44894 | K43: 460.02394 | L43: 14.093 | M43: 32.853 | N43: 1.023 | O43: 750.01 | P43: 0
A44: 43652 | B44: 0.66666667 | C44: =A44+B44 -> 43652.667 | D44: =D43 -> 525465 | E44: =E43 -> 6300495 | F44: =F43 -> 2536 | G44: 275 | H44: 35.2 | I44: 0.128 | J44: 286.0169 | K44: 443.5219 | L44: 13.904 | M44: 38.558 | N44: 1.577 | O44: 749.89 | P44: 0
A45: 43652 | B45: 0.6875 | C45: =A45+B45 -> 43652.688 | D45: =D44 -> 525465 | E45: =E44 -> 6300495 | F45: =F44 -> 2536 | G45: 570.3 | H45: 71.1 | I45: 0.12467123 | J45: 317.27815 | K45: 430.81415 | L45: 12.962 | M45: 42.603 | N45: 1.468 | O45: 750.275 | P45: 0
A46: 43652 | B46: 0.70833333 | C46: =A46+B46 -> 43652.708 | D46: =D45 -> 525465 | E46: =E45 -> 6300495 | F46: =F45 -> 2536 | G46: 451.3 | H46: 60.2 | I46: 0.13339242 | J46: 275.83607 | K46: 433.79607 | L46: 13.841 | M46: 38.077 | N46: 1.551 | O46: 750.057 | P46: 0
A47: 43652 | B47: 0.72916667 | C47: =A47+B47 -> 43652.729 | D47: =D46 -> 525465 | E47: =E46 -> 6300495 | F47: =F46 -> 2536 | G47: 453.2 | H47: 61.7 | I47: 0.13614298 | J47: 274.87458 | K47: 426.35658 | L47: 13.339 | M47: 37.719 | N47: 1.762 | O47: 750.22 | P47: 0
A48: 43652 | B48: 0.75 | C48: =A48+B48 -> 43652.75 | D48: =D47 -> 525465 | E48: =E47 -> 6300495 | F48: =F47 -> 2536 | G48: 108.1 | H48: 18.1 | I48: 0.16743756 | J48: 270.55069 | K48: 411.00269 | L48: 12.648 | M48: 38.068 | N48: 1.442 | O48: 750.105 | P48: 0
A49: 43652 | B49: 0.77083333 | C49: =A49+B49 -> 43652.771 | D49: =D48 -> 525465 | E49: =E48 -> 6300495 | F49: =F48 -> 2536 | G49: 259.5 | H49: 38.6 | I49: 0.14874759 | J49: 273.00206 | K49: 401.79006 | L49: 12.02 | M49: 40.462 | N49: 0.95 | O49: 750.155 | P49: 0
A50: 43652 | B50: 0.79166667 | C50: =A50+B50 -> 43652.792 | D50: =D49 -> 525465 | E50: =E49 -> 6300495 | F50: =F49 -> 2536 | G50: 88.4 | H50: 17.3 | I50: 0.19570136 | J50: 272.01199 | K50: 392.63499 | L50: 12.209 | M50: 37.313 | N50: 0.933 | O50: 750.247 | P50: 0
... A53: 43652 | B53: 0.85416667 | C53: =A53+B53 -> 43652.854 | D53: =D52 -> 525465 | E53: =E52 -> 6300495 | F53: =F52 -> 2536 | G53: 8.1 | H53: 7.1 | I53: 0.87654321 | J53: 266.48783 | K53: 367.82383 | L53: 10.827 | M53: 35.558 | N53: 0.474 | O53: 750.578 | P53: 0
A54: 43652 | B54: 0.875 | C54: =A54+B54 -> 43652.875 | D54: =D53 -> 525465 | E54: =E53 -> 6300495 | F54: =F53 -> 2536 | G54: 0 | H54: 0 | I54: NODATA | J54: 278.25281 | K54: 365.79081 | L54: 10.45 | M54: 38.765 | N54: 0.415 | O54: 750.682 | P54: 0
A55: 43652 | B55: 0.89583333 | C55: =A55+B55 -> 43652.896 | D55: =D54 -> 525465 | E55: =E54 -> 6300495 | F55: =F54 -> 2536 | G55: 0 | H55: 0 | I55: NODATA | J55: 274.84964 | K55: 361.00364 | L55: 10.575 | M55: 37.674 | N55: 0.269 | O55: 750.712 | P55: 0
A56: 43652 | B56: 0.91666667 | C56: =A56+B56 -> 43652.917 | D56: =D55 -> 525465 | E56: =E55 -> 6300495 | F56: =F55 -> 2536 | G56: 0 | H56: 0 | I56: NODATA | J56: 270.97782 | K56: 356.48482 | L56: 10.261 | M56: 42.21 | N56: 0.167 | O56: 750.915 | P56: 0
A57: 43652 | B57: 0.9375 | C57: =A57+B57 -> 43652.938 | D57: =D56 -> 525465 | E57: =E56 -> 6300495 | F57: =F56 -> 2536 | G57: 0 | H57: 0 | I57: NODATA | J57: 265.70587 | K57: 352.55287 | L57: 9.884 | M57: 48.933 | N57: 0.483 | O57: 750.915 | P57: 0
A58: 43652 | B58: 0.95833333 | C58: =A58+B58 -> 43652.958 | D58: =D57 -> 525465 | E58: =E57 -> 6300495 | F58: =F57 -> 2536 | G58: 0 | H58: 0 | I58: NODATA | J58: 261.80406 | K58: 350.27706 | L58: 9.633 | M58: 50.878 | N58: 0.143 | O58: 750.922 | P58: 0
A59: 43652 | B59: 0.97916667 | C59: =A59+B59 -> 43652.979 | D59: =D58 -> 525465 | E59: =E58 -> 6300495 | F59: =F58 -> 2536 | G59: 0 | H59: 0 | I59: NODATA | J59: 263.59646 | K59: 348.04946 | L59: 9.319 | M59: 52.328 | N59: 0.292 | O59: 750.903 | P59: 0
A60: 43653 | B60: 0 | C60: =A60+B60 -> 43653 | D60: =D59 -> 525465 | E60: =E59 -> 6300495 | F60: =F59 -> 2536 | G60: 0 | H60: 0 | I60: NODATA | J60: 257.29926 | K60: 343.04926 | L60: 9.193 | M60: 53.345 | N60: 0.111 | O60: 750.86 | P60: 0
A61: 43653 | B61: 0.020833333 | C61: =A61+B61 -> 43653.021 | D61: =D60 -> 525465 | E61: =E60 -> 6300495 | F61: =F60 -> 2536 | G61: 0 | H61: 0 | I61: NODATA | J61: 258.11408 | K61: 342.21908 | L61: 8.816 | M61: 55.409 | N61: 0.566 | O61: 750.773 | P61: 0
A62: 43653 | B62: 0.041666667 | C62: =A62+B62 -> 43653.042 | D62: =D61 -> 525465 | E62: =E61 -> 6300495 | F62: =F61 -> 2536 | G62: 0 | H62: 0 | I62: NODATA | J62: 258.85682 | K62: 339.98382 | L62: 9.633 | M62: 54.404 | N62: 0.484 | O62: 750.81 | P62: 0
A63: 43653 | B63: 0.0625 | C63: =A63+B63 -> 43653.062 | D63: =D62 -> 525465 | E63: =E62 -> 6300495 | F63: =F62 -> 2536 | G63: 0 | H63: 0 | I63: NODATA | J63: 259.45668 | K63: 339.62868 | L63: 9.256 | M63: 56.402 | N63: 0.868 | O63: 750.888 | P63: 0
...

Sheet AWS2_30min
G1: Вт/м2 | H1: Вт/м2 | I1: Вт/м2 | J1: °C | K1: % | L1: м/с | M1: гПа | N1: мм/30 мин
D2: Ячейка | E2: Ячейка | F2: Ячейка | G2: meas | H2: meas | I2: meas | J2: meas | K2: meas | L2: meas | M2: meas | N2: meas
A3: Дата | B3: Время | C3: Дата&Время | D3: X | E3: Y | F3: Z | G3: Sin | H3: Sout | I3: Lin | J3: T2m | K3: RH2m | L3: W2m | M3: p | N3: Prec | O3: α
A4: 43653 | B4: 0 | C4: =A4+B4 -> 43653 | D4: 525465 | E4: 6300765 | F4: 2549 | G4: 0 | H4: 0 | I4: 257.29926 | J4: 9.099 | K4: 54.517 | L4: 0.66288393 | M4: 750.86 | N4: 0 | O4: NODATA
A5: 43653 | B5: 0.020833333 | C5: =A5+B5 -> 43653.021 | D5: =D4 -> 525465 | E5: =E4 -> 6300765 | F5: =F4 -> 2549 | G5: 0 | H5: 0 | I5: 258.11408 | J5: 9.852 | K5: 52.89 | L5: 1.0936265 | M5: 750.773 | N5: 0 | O5: NODATA
A6: 43653 | B6: 0.041666667 | C6: =A6+B6 -> 43653.042 | D6: =D5 -> 525465 | E6: =E5 -> 6300765 | F6: =F5 -> 2549 | G6: 0 | H6: 0 | I6: 258.85682 | J6: 9.287 | K6: 56.082 | L6: 1.091352 | M6: 750.81 | N6: 0 | O6: NODATA
A7: 43653 | B7: 0.0625 | C7: =A7+B7 -> 43653.062 | D7: =D6 -> 525465 | E7: =E6 -> 6300765 | F7: =F6 -> 2549 | G7: 0 | H7: 0 | I7: 259.45668 | J7: 8.659 | K7: 59.279 | L7: 1.5223817 | M7: 750.888 | N7: 0 | O7: NODATA
A8: 43653 | B8: 0.083333333 | C8: =A8+B8 -> 43653.083 | D8: =D7 -> 525465 | E8: =E7 -> 6300765 | F8: =F7 -> 2549 | G8: 0 | H8: 0 | I8: 261.88299 | J8: 10.166 | K8: 54.545 | L8: 1.3756725 | M8: 750.995 | N8: 0 | O8: NODATA
A9: 43653 | B9: 0.10416667 | C9: =A9+B9 -> 43653.104 | D9: =D8 -> 525465 | E9: =E8 -> 6300765 | F9: =F8 -> 2549 | G9: 0 | H9: 0 | I9: 260.0065 | J9: 9.475 | K9: 55.708 | L9: 1.6622675 | M9: 751.115 | N9: 0 | O9: NODATA
A10: 43653 | B10: 0.125 | C10: =A10+B10 -> 43653.125 | D10: =D9 -> 525465 | E10: =E9 -> 6300765 | F10: =F9 -> 2549 | G10: 0 | H10: 0 | I10: 259.83447 | J10: 9.915 | K10: 53.133 | L10: 1.8044278 | M10: 751.177 | N10: 0 | O10: NODATA
A11: 43653 | B11: 0.14583333 | C11: =A11+B11 -> 43653.146 | D11: =D10 -> 525465 | E11: =E10 -> 6300765 | F11: =F10 -> 2549 | G11: 0 | H11: 0 | I11: 259.27442 | J11: 10.04 | K11: 52.398 | L11: 1.9463009 | M11: 751.2 | N11: 0 | O11: NODATA
A12: 43653 | B12: 0.16666667 | C12: =A12+B12 -> 43653.167 | D12: =D11 -> 525465 | E12: =E11 -> 6300765 | F12: =F11 -> 2549 | G12: 9.1 | H12: 7.2 | I12: 258.17463 | J12: 10.103 | K12: 51.183 | L12: 1.9440264 | M12: 751.138 | N12: 0 | O12: 0.79120879
A13: 43653 | B13: 0.1875 | C13: =A13+B13 -> 43653.188 | D13: =D12 -> 525465 | E13: =E12 -> 6300765 | F13: =F12 -> 2549 | G13: 21.8 | H13: 16.2 | I13: 258.69445 | J13: 10.166 | K13: 51.19 | L13: 2.3750561 | M13: 751.027 | N13: 0 | O13: 0.74311927
A14: 43653 | B14: 0.20833333 | C14: =A14+B14 -> 43653.208 | D14: =D13 -> 525465 | E14: =E13 -> 6300765 | F14: =F13 -> 2549 | G14: 81.6 | H14: 70.2 | I14: 259.51381 | J14: 10.48 | K14: 49.909 | L14: 2.3727816 | M14: 750.815 | N14: 0 | O14: 0.86029412
A15: 43653 | B15: 0.22916667 | C15: =A15+B15 -> 43653.229 | D15: =D14 -> 525465 | E15: =E14 -> 6300765 | F15: =F14 -> 2549 | G15: 145.1 | H15: 111.5 | I15: 260.09667 | J15: 12.739 | K15: 43.871 | L15: 1.6486206 | M15: 751.002 | N15: 0 | O15: 0.76843556
A16: 43653 | B16: 0.25 | C16: =A16+B16 -> 43653.25 | D16: =D15 -> 525465 | E16: =E15 -> 6300765 | F16: =F15 -> 2549 | G16: 230.3 | H16: 167.3 | I16: 260.66197 | J16: 13.241 | K16: 41.524 | L16: 1.3574766 | M16: 751.04 | N16: 0 | O16: 0.72644377
A17: 43653 | B17: 0.27083333 | C17: =A17+B17 -> 43653.271 | D17: =D16 -> 525465 | E17: =E16 -> 6300765 | F17: =F16 -> 2549 | G17: 295.6 | H17: 210.5 | I17: 264.02413 | J17: 12.425 | K17: 44.091 | L17: 1.3552021 | M17: 750.958 | N17: 0 | O17: 0.71211096
A18: 43653 | B18: 0.29166667 | C18: =A18+B18 -> 43653.292 | D18: =D17 -> 525465 | E18: =E17 -> 6300765 | F18: =F17 -> 2549 | G18: 382.7 | H18: 271.7 | I18: 264.41693 | J18: 13.617 | K18: 40.992 | L18: 1.2084929 | M18: 751.027 | N18: 0 | O18: 0.70995558
A19: 43653 | B19: 0.3125 | C19: =A19+B19 -> 43653.312 | D19: =D18 -> 525465 | E19: =E18 -> 6300765 | F19: =F18 -> 2549 | G19: 455.2 | H19: 322 | I19: 268.34201 | J19: 13.617 | K19: 41.744 | L19: 1.3506531 | M19: 751.18 | N19: 0 | O19: 0.70738137
A20: 43653 | B20: 0.33333333 | C20: =A20+B20 -> 43653.333 | D20: =D19 -> 525465 | E20: =E19 -> 6300765 | F20: =F19 -> 2549 | G20: 516.9 | H20: 361.6 | I20: 269.04595 | J20: 13.868 | K20: 41.282 | L20: 1.2039439 | M20: 751.285 | N20: 0 | O20: 0.69955504
A21: 43653 | B21: 0.35416667 | C21: =A21+B21 -> 43653.354 | D21: =D20 -> 525465 | E21: =E20 -> 6300765 | F21: =F20 -> 2549 | G21: 589.4 | H21: 406.6 | I21: 273.35496 | J21: 14.182 | K21: 39.356 | L21: 1.2016694 | M21: 751.335 | N21: 0 | O21: 0.68985409
A22: 43653 | B22: 0.375 | C22: =A22+B22 -> 43653.375 | D22: =D21 -> 525465 | E22: =E21 -> 6300765 | F22: =F21 -> 2549 | G22: 658.4 | H22: 449.8 | I22: 277.65594 | J22: 16.815 | K22: 32.896 | L22: 2.0657162 | M22: 751.41 | N22: 0 | O22: 0.68317132
A23: 43653 | B23: 0.39583333 | C23: =A23+B23 -> 43653.396 | D23: =D22 -> 525465 | E23: =E22 -> 6300765 | F23: =F22 -> 2549 | G23: 711 | H23: 478.6 | I23: 277.28709 | J23: 15.749 | K23: 36.269 | L23: 1.7748594 | M23: 751.258 | N23: 0 | O23: 0.67313643
... A45: 43653 | B45: 0.85416667 | C45: =A45+B45 -> 43653.854 | D45: =D44 -> 525465 | E45: =E44 -> 6300765 | F45: =F44 -> 2549 | G45: 7.3 | H45: 3.6 | I45: 312.19306 | J45: 11.358 | K45: 50.442 | L45: 0.56962981 | M45: 750.333 | N45: 0 | O45: 0.49315068
A46: 43653 | B46: 0.875 | C46: =A46+B46 -> 43653.875 | D46: =D45 -> 525465 | E46: =E45 -> 6300765 | F46: =F45 -> 2549 | G46: 0 | H46: 0 | I46: 315.33001 | J46: 11.107 | K46: 52.003 | L46: 0.42292058 | M46: 750.372 | N46: 0 | O46: NODATA
A47: 43653 | B47: 0.89583333 | C47: =A47+B47 -> 43653.896 | D47: =D46 -> 525465 | E47: =E46 -> 6300765 | F47: =F46 -> 2549 | G47: 0 | H47: 0 | I47: 319.3099 | J47: 10.731 | K47: 55.452 | L47: 0.56508083 | M47: 750.387 | N47: 0 | O47: NODATA
A48: 43653 | B48: 0.91666667 | C48: =A48+B48 -> 43653.917 | D48: =D47 -> 525465 | E48: =E47 -> 6300765 | F48: =F47 -> 2549 | G48: 0 | H48: 0 | I48: 322.11238 | J48: 10.354 | K48: 56.929 | L48: 0.70695393 | M48: 750.258 | N48: 0 | O48: NODATA
A49: 43653 | B49: 0.9375 | C49: =A49+B49 -> 43653.938 | D49: =D48 -> 525465 | E49: =E48 -> 6300765 | F49: =F48 -> 2549 | G49: 0 | H49: 0 | I49: 307.708 | J49: 10.229 | K49: 58.309 | L49: 0.41609711 | M49: 750.085 | N49: 0 | O49: NODATA
A50: 43653 | B50: 0.95833333 | C50: =A50+B50 -> 43653.958 | D50: =D49 -> 525465 | E50: =E49 -> 6300765 | F50: =F49 -> 2549 | G50: 0 | H50: 0 | I50: 316.06396 | J50: 9.601 | K50: 59.058 | L50: 0.70240495 | M50: 749.888 | N50: 0 | O50: NODATA
A51: 43653 | B51: 0.97916667 | C51: =A51+B51 -> 43653.979 | D51: =D50 -> 525465 | E51: =E50 -> 6300765 | F51: =F50 -> 2549 | G51: 0 | H51: 0 | I51: 318.25198 | J51: 9.727 | K51: 58.185 | L51: 0.70013046 | M51: 749.718 | N51: 0 | O51: NODATA
A52: 43654 | B52: 0 | C52: =A52+B52 -> 43654 | D52: =D51 -> 525465 | E52: =E51 -> 6300765 | F52: =F51 -> 2549 | G52: 0 | H52: 0 | I52: 320.84798 | J52: 9.35 | K52: 58.93 | L52: 0.95146626 | M52: 749.785 | N52: 0 | O52: NODATA
A53: 43654 | B53: 0.020833333 | C53: =A53+B53 -> 43654.021 | D53: =D52 -> 525465 | E53: =E52 -> 6300765 | F53: =F52 -> 2549 | G53: 0 | H53: 0 | I53: 329.93799 | J53: 9.475 | K53: 58.313 | L53: 0.37173996 | M53: 749.59 | N53: 0 | O53: NODATA
A54: 43654 | B54: 0.041666667 | C54: =A54+B54 -> 43654.042 | D54: =D53 -> 525465 | E54: =E53 -> 6300765 | F54: =F53 -> 2549 | G54: 0 | H54: 0 | I54: 328.76221 | J54: 9.35 | K54: 60.452 | L54: 0.22503073 | M54: 749.41 | N54: 0 | O54: NODATA
A55: 43654 | B55: 0.0625 | C55: =A55+B55 -> 43654.062 | D55: =D54 -> 525465 | E55: =E54 -> 6300765 | F55: =F54 -> 2549 | G55: 0 | H55: 0 | I55: 326.79434 | J55: 9.538 | K55: 58.891 | L55: 0.22275624 | M55: 749.302 | N55: 0 | O55: NODATA
A56: 43654 | B56: 0.083333333 | C56: =A56+B56 -> 43654.083 | D56: =D55 -> 525465 | E56: =E55 -> 6300765 | F56: =F55 -> 2549 | G56: 0 | H56: 0 | I56: 326.4112 | J56: 9.413 | K56: 59.351 | L56: 0.22048175 | M56: 749.227 | N56: 0 | O56: NODATA
A57: 43654 | B57: 0.10416667 | C57: =A57+B57 -> 43654.104 | D57: =D56 -> 525465 | E57: =E56 -> 6300765 | F57: =F56 -> 2549 | G57: 0 | H57: 0 | I57: 329.62312 | J57: 8.785 | K57: 61.863 | L57: 0.50707674 | M57: 749.1 | N57: 0 | O57: NODATA
... A60: 43654 | B60: 0.16666667 | C60: =A60+B60 -> 43654.167 | D60: =D59 -> 525465 | E60: =E59 -> 6300765 | F60: =F59 -> 2549 | G60: 0 | H60: 0 | I60: 330.20584 | J60: 8.91 | K60: 61.662 | L60: 0.35581852 | M60: 748.845 | N60: 0 | O60: NODATA
A61: 43654 | B61: 0.1875 | C61: =A61+B61 -> 43654.188 | D61: =D60 -> 525465 | E61: =E60 -> 6300765 | F61: =F60 -> 2549 | G61: 3.6 | H61: 1.8 | I61: 330.31553 | J61: 8.973 | K61: 62.145 | L61: 0.20910929 | M61: 748.94 | N61: 0 | O61: 0.5
A62: 43654 | B62: 0.20833333 | C62: =A62+B62 -> 43654.208 | D62: =D61 -> 525465 | E62: =E61 -> 6300765 | F62: =F61 -> 2549 | G62: 18.1 | H62: 10.8 | I62: 331.66766 | J62: 9.036 | K62: 61.837 | L62: 0.35126954 | M62: 748.797 | N62: 0 | O62: 0.59668508
A63: 43654 | B63: 0.22916667 | C63: =A63+B63 -> 43654.229 | D63: =D62 -> 525465 | E63: =E62 -> 6300765 | F63: =F62 -> 2549 | G63: 34.5 | H63: 21.6 | I63: 328.59406 | J63: 8.848 | K63: 64.502 | L63: 0.63786453 | M63: 748.758 | N63: 0 | O63: 0.62608696
...

Sheet Const
A1: Параметр | B1: Значение | C1: Ед. изм. | D1: Тип | E1: Описание
A2: ε | B2: 1 | C2: б/разм | D2: константа | E2: излучательная способность поверхности
A3: Ts | B3: 0 | C3: °C | D3: константа | E3: температура поверхности ледника
A4: Ts | B4: =B3+273.15 -> 273.15 | C4: K | D4: константа | E4: температура поверхности
A5: σ | B5: 5.67e-08 | C5: Вт/ (м2 К4) | D5: константа | E5: постоянная Стефана-Больцмана
A6: g | B6: 9.81 | C6: м/с2 | D6: константа | E6: ускорение свободного падения
A7: cp | B7: 1010 | C7: Дж/(кг К) | D7: константа | E7: удельная теплоемкость воздуха при постоянном давлении
A8: ρ0 | B8: 1.29 | C8: кг/м3 | D8: константа | E8: плотность воздуха на стандартном уровне моря
A9: k | B9: 0.38 | C9: б/разм | D9: константа | E9: постоянная Кармана
A10: Lv | B10: 2514000 | C10: Дж/кг | D10: константа | E10: скрытая теплота испарения снега/льда для тающей поверхности
A11: p0 | B11: 1013 | C11: гПа | D11: константа | E11: атмосферное давление на стандартном уровне моря
A12: es | B12: 6.11 | C12: гПа | D12: константа | E12: давление водяного пара на поверхности ледника при 0°C
A13: ρw | B13: 980 | C13: кг/м3 | D13: константа | E13: плотность воды
A14: cw | B14: 4190 | C14: Дж/(кг К) | D14: константа | E14: теплоемкость воды
A15: kτs | B15: 0.4 | C15: Вт/ (м К) | D15: константа | E15: теплопроводность снега
A16: kτi | B16: 2.2 | C16: Вт/ (м К) | D16: константа | E16: теплопроводность льда
... A30: t-2m | B30: -1.7 | C30: °C | D30: переменная | E30: температура льда на глубине 2 м
A31: t-2m | B31: =B30+273.15 -> 271.45 | C31: K | D31: переменная | E31: температура льда на глубине 2 м
A32: zs | B32: 2 | C32: м | D32: переменная | E32: высота прибора над поверхностью ледника
A33: Rib(cr) | B33: 0.4 | C33: б/разм | D33: переменная | E33: критическое значение числа Ричардсона
A34: Z0m | B34: 0.00061 | C34: м | D34: переменная | E34: длина шероховатости поверхности для момента
A35: Z0t | B35: 0.00043 | C35: м | D35: переменная | E35: длина шероховатости поверхности для температуры
A36: Z0h | B36: 0.00049 | C36: м | D36: переменная | E36: длина шероховатости поверхности для влажности
A37: ρsnow | B37: 602 | C37: кг/м3 | D37: переменная | E37: средняя плотность снега
A38: ρice | B38: 784 | C38: кг/м3 | D38: переменная | E38: средняя плотность льда

Sheet Model_30min
E1: номер ячейки | F1: ледниковые ячейки | G1: метеостанция на морене | H1: метеостанция на леднике | I1: примечание | J1: x-координата ячейки | K1: y-координата ячейки | L1: абсолютная высота ячейки | M1: уклон ячейки | N1: экспозиция ячейки | O1: глобальная (суммарная) радиация (r.sun) | P1: приходящая КВ-радиация на метестанции AWS2 | Q1: глобальная (суммарная) радиация в ячейке метеостанции AWS2 | R1: соотношение | S1: приходящая КВ-радиация | T1: день со снегопадом на леднике | U1: высота снеговой линии на леднике | V1: тип поверхности | W1: средняя суточная температура на уровне 2 м | X1: число дней после последнего снегопада на леднике | Y1: сумма температур воздуха со дня со снегопадом | Z1: альбедо поверхности | AA1: отраженная КВ-радиация | AB1: баланс КВ-радиации | AC1: длинноволновое излучение атмосферы | AD1: длинноволновое излучение поверхности ледника | AE1: баланс ДВ-радиации | AF1: радиационный баланс | AG1: температура воздуха на уровне 2 м | AH1: температура воздуха на уровне 2 м | AI1: относительная влажность воздуха на уровне 2 м | AJ1: скорость ветра | AK1: число Ричардсона | AL1: число Ричардсона (коррекция) | AM1: безразмерные функции | AN1: средняя температура слоя воздуха между метеостанцией на морене (AWS1) и данной ячейкой | AO1: атмосферное давление | AP1: явное турбулентное тепло | AQ1: явное турбулентное тепло (коррекция) | AR1: давление водяного пара во влажном воздухе | AS1: скрытое турбулентное тепло | AT1: скрытое турбулентное тепло (коррекция) | AU1: суммарное турбулентное тепло | AV1: атмосферные осадки | AW1: атмосферные осадки (жидкие) | AX1: тепло поступающее с жидкими осадками | AY1: тепло расходуемое на теплообмен с ледником | AZ1: тепло расходуемое на таяние | BA1: плотность снега или льда | BB1: абляция (таяние)
F2: бинарный | G2: бинарный | H2: бинарный | J2: м | K2: м | L2: м | M2: градусы | N2: градусы | O2: Вт/м2 | P2: Вт/м2 | Q2: Вт/м2 | R2: б/разм | S2: Вт/м2 | T2: бинарный | U2: м | V2: бинарный | W2: °C | X2: дни | Y2: °C | Z2: б/разм | AA2: Вт/м2 | AB2: Вт/м2 | AC2: Вт/м2 | AD2: Вт/м2 | AE2: Вт/м2 | AF2: Вт/м2 | AG2: °C | AH2: K | AI2: % | AJ2: м/с | AN2: °C | AO2: гПа | AP2: Вт/м2 | AQ2: Вт/м2 | AR2: гПа | AS2: Вт/м2 | AT2: Вт/м2 | AU2: Вт/м2 | AV2: мм/30 мин | AW2: м/с | AX2: Вт/м2 | AY2: Вт/м2 | AZ2: Вт/м2 | BA2: кг/м3 | BB2: мм/30 мин
A3: Дата | B3: Время | C3: Дата&Время | D3: День года | E3: No | F3: Ледник | G3: AWS1 | H3: AWS2 | I3: Note (AWS) | J3: X | K3: Y | L3: Z | M3: Уклон | N3: Экспозиция | O3: G | P3: Sin(AWS2) | Q3: G(AWS2) | R3: Sin(AWS2)/G(AWS2) | S3: Sin | T3: SD | U3: Zsl | V3: ST | W3: T2m (d) | X3: nd | Y3: Ta | Z3: α | AA3: Sout | AB3: Snet | AC3: Lin | AD3: Lout | AE3: Lnet | AF3: Rnet | AG3: T2m (30 min) | AH3: T2m (30 min) | AI3: RH2m (30 min) | AJ3: WS2m (30 min) | AK3: Rib | AL3: Rib_corr | AM3: f(Rib) | AN3: T | AO3: p | AP3: H | AQ3: H+f(Rib) | AR3: e2m | AS3: LE | AT3: LE+f(Rib) | AU3: H+LE | AV3: Precip | AW3: Precip_liq | AX3: QR | AY3: QG | AZ3: Qm | BA3: ρ | BB3: A
A4: 43653 | B4: 0.5 | C4: =A4+B4 -> 43653.5 | D4: =A4-DATE(YEAR(C4),1,0) -> 188 | E4: 1 | F4: 0 | G4: 0 | H4: 0 | J4: 524475 | K4: 6301125 | L4: 2326 | M4: 17.1422 | N4: 51.5819 | O4: 744.495 | P4: =VLOOKUP(C4,AWS2_30min!$C$3:$G$2935,5) -> 955.8 | Q4: =INDEX($O$4:$O$423,MATCH(1,$H$4:$H$423,0)) -> 856.334 | R4: =P4/Q4 -> 1.1161533 | S4: =IF(F4=1,R4*O4) -> FALSE | T4: =VLOOKUP(A4,Albedo!$A$2:$F$63,6) -> 0 | U4: =Const!$B$26*D4+Const!$B$27 -> 2402.4844 | V4: =IF(T4=1,1,IF(L4>=U4,1,0)) -> 0 | W4: =VLOOKUP(A4,Albedo!$A$2:$G$63,5)+Const!$B$20*(L4-Const!$B$29) -> 18.8445 | X4: =VLOOKUP(A4,Albedo!$A$2:$G$63,7) -> 3 | Y4: =IF(T4=1,W4,VLOOKUP(A4,Albedo!$A$2:$H$63,8)+(X4+1)*Const!$B$20*(L4-Const!$B$29)) -> 41.11 | Z4: =Const!$B$22*V4+Const!$B$23*W4+Const!$B$24*Y4+Const!$B$25 -> 0.24656371 | AA4: =IF(F4=1,S4*Z4) -> FALSE | AB4: =IF(F4=1,S4-AA4) -> FALSE | AC4: =IF(F4=1,VLOOKUP(C4,AWS1_30min!$C$3:$J$2747,8)) -> FALSE | AD4: =IF(F4=1,Const!$B$5*POWER((0+Const!$B$4),4)) -> FALSE | AE4: =IF(F4=1,AC4-AD4) -> FALSE | AF4: =IF(F4=1,AB4+AE4) -> FALSE | AG4: =VLOOKUP(C4,AWS2_30min!$C$3:$J$2935,8)+Const!$B$20*(L4-Const!$B$29) -> 18.8445 | AH4: =AG4+273.15 -> 291.9945 | AI4: =VLOOKUP(C4,AWS2_30min!$C$3:$K$2935,9) -> 30.97 | AJ4: =VLOOKUP(C4,AWS2_30min!$C$3:$L$2935,10) -> 1.9076345 | AK4: =IF(AJ4>0.5,Const!$B$6*(AH4-Const!$B$4)*(Const!$B$32-Const!$B$34)/(AH4*POWER(AJ4,2))) -> 0.34784529 | AL4: =IF(AK4<Const!$B$33,AK4,"ЛОЖЬ") -> 0.34784529 | AM4: =IF(AND(ISNUMBER(AL4),AL4>0),POWER((1-5*AL4),2),IF(ISNUMBER(AL4),POWER((1-16*AL4),0.75))) -> 0.54645574 | AN4: =(AG4+VLOOKUP(C4,AWS1_30min!$C$4:$L$2747,10))/2 -> 16.81375 | AO4: =VLOOKUP(C4,AWS1_30min!$C$4:$O$2747,13)/POWER(10,(L4-Const!$B$28)/18400*(1+0.003665*AN4)) -> 771.56316 | AP4: =Const!$B$7*Const!$B$8*(AO4/Const!$B$11)*POWER(Const!$B$9,2)*AJ4*(AH4-Const!$B$4)/(LN(Const!$B$32/Const!$B$34)*LN(Const!$B$32/Const!$B$35)) -> 75.352817 | AQ4: =IF(F4=1,AM4*AP4) -> FALSE | AR4: =AI4*((6.112*EXP(((17.62*AG4)/(243.12+AG4))))*(1.0016+0.0000315*AO4-0.074/AO4))/100 -> 6.8969833 | AS4: =0.623*Const!$B$10*Const!$B$8*POWER(Const!$B$9,2)*AJ4*(AR4-Const!$B$12)/1013/(LN(Const!$B$32/Const!$B$34)*LN(Const!$B$32/Const!$B$36)) -> 6.4240767 | AT4: =IF(F4=1,AM4*AS4) -> FALSE | AU4: =IF(F4=1,AQ4+AT4) -> FALSE | AV4: =VLOOKUP(C4,AWS1_30min!$C$4:$P$2747,14) -> 0 | AW4: =IF(AG4>=2,AV4/1000/1800) -> 0 | AX4: =IF(F4=1,AW4*Const!$B$13*Const!$B$14*(AH4-Const!$B$4)) -> FALSE | AY4: =IF(F4=1,-Const!$B$15*(Const!$B$4-Const!$B$31)/2) -> FALSE | AZ4: =IF(F4=1,AB4+AE4+AQ4+AT4+AY4+AX4) -> FALSE | BA4: =IF(V4=1,Const!$B$37,Const!$B$38) -> 784 | BB4: =IF(F4=1,AZ4/Const!$B$17*1800/BA4*1000) -> FALSE
A5: =A4 -> 43653 | B5: =B4 -> 0.5 | C5: =C4 -> 43653.5 | D5: =D4 -> 188 | E5: 2 | F5: 0 | G5: 0 | H5: 0 | J5: 524565 | K5: 6301125 | L5: 2307 | M5: 12.2699 | N5: 28.2016 | O5: 840.349 | P5: =VLOOKUP(C5,AWS2_30min!$C$3:$G$2935,5) -> 955.8 | Q5: =INDEX($O$4:$O$423,MATCH(1,$H$4:$H$423,0)) -> 856.334 | R5: =P5/Q5 -> 1.1161533 | S5: =IF(F5=1,R5*O5) -> FALSE | T5: =VLOOKUP(A5,Albedo!$A$2:$F$63,6) -> 0 | U5: =Const!$B$26*D5+Const!$B$27 -> 2402.4844 | V5: =IF(T5=1,1,IF(L5>=U5,1,0)) -> 0 | W5: =VLOOKUP(A5,Albedo!$A$2:$G$63,5)+Const!$B$20*(L5-Const!$B$29) -> 18.968 | X5: =VLOOKUP(A5,Albedo!$A$2:$G$63,7) -> 3 | Y5: =IF(T5=1,W5,VLOOKUP(A5,Albedo!$A$2:$H$63,8)+(X5+1)*Const!$B$20*(L5-Const!$B$29)) -> 41.604 | Z5: =Const!$B$22*V5+Const!$B$23*W5+Const!$B$24*Y5+Const!$B$25 -> 0.24704536 | AA5: =IF(F5=1,S5*Z5) -> FALSE | AB5: =IF(F5=1,S5-AA5) -> FALSE | AC5: =IF(F5=1,VLOOKUP(C5,AWS1_30min!$C$3:$J$2747,8)) -> FALSE | AD5: =IF(F5=1,Const!$B$5*POWER((0+Const!$B$4),4)) -> FALSE | AE5: =IF(F5=1,AC5-AD5) -> FALSE | AF5: =IF(F5=1,AB5+AE5) -> FALSE | AG5: =VLOOKUP(C5,AWS2_30min!$C$3:$J$2935,8)+Const!$B$20*(L5-Const!$B$29) -> 18.968 | AH5: =AG5+273.15 -> 292.118 | AI5: =VLOOKUP(C5,AWS2_30min!$C$3:$K$2935,9) -> 30.97 | AJ5: =VLOOKUP(C5,AWS2_30min!$C$3:$L$2935,10) -> 1.9076345 | AK5: =IF(AJ5>0.5,Const!$B$6*(AH5-Const!$B$4)*(Const!$B$32-Const!$B$34)/(AH5*POWER(AJ5,2))) -> 0.34997692 | AL5: =IF(AK5<Const!$B$33,AK5,"ЛОЖЬ") -> 0.34997692 | AM5: =IF(AND(ISNUMBER(AL5),AL5>0),POWER((1-5*AL5),2),IF(ISNUMBER(AL5),POWER((1-16*AL5),0.75))) -> 0.56232689 | AN5: =(AG5+VLOOKUP(C5,AWS1_30min!$C$4:$L$2747,10))/2 -> 16.8755 | AO5: =VLOOKUP(C5,AWS1_30min!$C$4:$O$2747,13)/POWER(10,(L5-Const!$B$28)/18400*(1+0.003665*AN5)) -> 773.51806 | AP5: =Const!$B$7*Const!$B$8*(AO5/Const!$B$11)*POWER(Const!$B$9,2)*AJ5*(AH5-Const!$B$4)/(LN(Const!$B$32/Const!$B$34)*LN(Const!$B$32/Const!$B$35)) -> 76.038823 | AQ5: =IF(F5=1,AM5*AP5) -> FALSE | AR5: =AI5*((6.112*EXP(((17.62*AG5)/(243.12+AG5))))*(1.0016+0.0000315*AO5-0.074/AO5))/100 -> 6.9507525 | AS5: =0.623*Const!$B$10*Const!$B$8*POWER(Const!$B$9,2)*AJ5*(AR5-Const!$B$12)/1013/(LN(Const!$B$32/Const!$B$34)*LN(Const!$B$32/Const!$B$36)) -> 6.8629905 | AT5: =IF(F5=1,AM5*AS5) -> FALSE | AU5: =IF(F5=1,AQ5+AT5) -> FALSE | AV5: =VLOOKUP(C5,AWS1_30min!$C$4:$P$2747,14) -> 0 | AW5: =IF(AG5>=2,AV5/1000/1800) -> 0 | AX5: =IF(F5=1,AW5*Const!$B$13*Const!$B$14*(AH5-Const!$B$4)) -> FALSE | AY5: =IF(F5=1,-Const!$B$15*(Const!$B$4-Const!$B$31)/2) -> FALSE | AZ5: =IF(F5=1,AB5+AE5+AQ5+AT5+AY5+AX5) -> FALSE | BA5: =IF(V5=1,Const!$B$37,Const!$B$38) -> 784 | BB5: =IF(F5=1,AZ5/Const!$B$17*1800/BA5*1000) -> FALSE
A6: =A5 -> 43653 | B6: =B5 -> 0.5 | C6: =C5 -> 43653.5 | D6: =D5 -> 188 | E6: 3 | F6: 0 | G6: 0 | H6: 0 | J6: 524655 | K6: 6301125 | L6: 2307 | M6: 11.8448 | N6: 0.379439 | O6: 901.779 | P6: =VLOOKUP(C6,AWS2_30min!$C$3:$G$2935,5) -> 955.8 | Q6: =INDEX($O$4:$O$423,MATCH(1,$H$4:$H$423,0)) -> 856.334 | R6: =P6/Q6 -> 1.1161533 | S6: =IF(F6=1,R6*O6) -> FALSE | T6: =VLOOKUP(A6,Albedo!$A$2:$F$63,6) -> 0 | U6: =Const!$B$26*D6+Const!$B$27 -> 2402.4844 | V6: =IF(T6=1,1,IF(L6>=U6,1,0)) -> 0 | W6: =VLOOKUP(A6,Albedo!$A$2:$G$63,5)+Const!$B$20*(L6-Const!$B$29) -> 18.968 | X6: =VLOOKUP(A6,Albedo!$A$2:$G$63,7) -> 3 | Y6: =IF(T6=1,W6,VLOOKUP(A6,Albedo!$A$2:$H$63,8)+(X6+1)*Const!$B$20*(L6-Const!$B$29)) -> 41.604 | Z6: =Const!$B$22*V6+Const!$B$23*W6+Const!$B$24*Y6+Const!$B$25 -> 0.24704536 | AA6: =IF(F6=1,S6*Z6) -> FALSE | AB6: =IF(F6=1,S6-AA6) -> FALSE | AC6: =IF(F6=1,VLOOKUP(C6,AWS1_30min!$C$3:$J$2747,8)) -> FALSE | AD6: =IF(F6=1,Const!$B$5*POWER((0+Const!$B$4),4)) -> FALSE | AE6: =IF(F6=1,AC6-AD6) -> FALSE | AF6: =IF(F6=1,AB6+AE6) -> FALSE | AG6: =VLOOKUP(C6,AWS2_30min!$C$3:$J$2935,8)+Const!$B$20*(L6-Const!$B$29) -> 18.968 | AH6: =AG6+273.15 -> 292.118 | AI6: =VLOOKUP(C6,AWS2_30min!$C$3:$K$2935,9) -> 30.97 | AJ6: =VLOOKUP(C6,AWS2_30min!$C$3:$L$2935,10) -> 1.9076345 | AK6: =IF(AJ6>0.5,Const!$B$6*(AH6-Const!$B$4)*(Const!$B$32-Const!$B$34)/(AH6*POWER(AJ6,2))) -> 0.34997692 | AL6: =IF(AK6<Const!$B$33,AK6,"ЛОЖЬ") -> 0.34997692 | AM6: =IF(AND(ISNUMBER(AL6),AL6>0),POWER((1-5*AL6),2),IF(ISNUMBER(AL6),POWER((1-16*AL6),0.75))) -> 0.56232689 | AN6: =(AG6+VLOOKUP(C6,AWS1_30min!$C$4:$L$2747,10))/2 -> 16.8755 | AO6: =VLOOKUP(C6,AWS1_30min!$C$4:$O$2747,13)/POWER(10,(L6-Const!$B$28)/18400*(1+0.003665*AN6)) -> 773.51806 | AP6: =Const!$B$7*Const!$B$8*(AO6/Const!$B$11)*POWER(Const!$B$9,2)*AJ6*(AH6-Const!$B$4)/(LN(Const!$B$32/Const!$B$34)*LN(Const!$B$32/Const!$B$35)) -> 76.038823 | AQ6: =IF(F6=1,AM6*AP6) -> FALSE | AR6: =AI6*((6.112*EXP(((17.62*AG6)/(243.12+AG6))))*(1.0016+0.0000315*AO6-0.074/AO6))/100 -> 6.9507525 | AS6: =0.623*Const!$B$10*Const!$B$8*POWER(Const!$B$9,2)*AJ6*(AR6-Const!$B$12)/1013/(LN(Const!$B$32/Const!$B$34)*LN(Const!$B$32/Const!$B$36)) -> 6.8629905 | AT6: =IF(F6=1,AM6*AS6) -> FALSE | AU6: =IF(F6=1,AQ6+AT6) -> FALSE | AV6: =VLOOKUP(C6,AWS1_30min!$C$4:$P$2747,14) -> 0 | AW6: =IF(AG6>=2,AV6/1000/1800) -> 0 | AX6: =IF(F6=1,AW6*Const!$B$13*Const!$B$14*(AH6-Const!$B$4)) -> FALSE | AY6: =IF(F6=1,-Const!$B$15*(Const!$B$4-Const!$B$31)/2) -> FALSE | AZ6: =IF(F6=1,AB6+AE6+AQ6+AT6+AY6+AX6) -> FALSE | BA6: =IF(V6=1,Const!$B$37,Const!$B$38) -> 784 | BB6: =IF(F6=1,AZ6/Const!$B$17*1800/BA6*1000) -> FALSE
A7: =A6 -> 43653 | B7: =B6 -> 0.5 | C7: =C6 -> 43653.5 | D7: =D6 -> 188 | E7: 4 | F7: 0 | G7: 0 | H7: 0 | J7: 524745 | K7: 6301125 | L7: 2304 | M7: 21.7408 | N7: 315.847 | O7: 1020.33 | P7: =VLOOKUP(C7,AWS2_30min!$C$3:$G$2935,5) -> 955.8 | Q7: =INDEX($O$4:$O$423,MATCH(1,$H$4:$H$423,0)) -> 856.334 | R7: =P7/Q7 -> 1.1161533 | S7: =IF(F7=1,R7*O7) -> FALSE | T7: =VLOOKUP(A7,Albedo!$A$2:$F$63,6) -> 0 | U7: =Const!$B$26*D7+Const!$B$27 -> 2402.4844 | V7: =IF(T7=1,1,IF(L7>=U7,1,0)) -> 0 | W7: =VLOOKUP(A7,Albedo!$A$2:$G$63,5)+Const!$B$20*(L7-Const!$B$29) -> 18.9875 | X7: =VLOOKUP(A7,Albedo!$A$2:$G$63,7) -> 3 | Y7: =IF(T7=1,W7,VLOOKUP(A7,Albedo!$A$2:$H$63,8)+(X7+1)*Const!$B$20*(L7-Const!$B$29)) -> 41.682 | Z7: =Const!$B$22*V7+Const!$B$23*W7+Const!$B$24*Y7+Const!$B$25 -> 0.24712141 | AA7: =IF(F7=1,S7*Z7) -> FALSE | AB7: =IF(F7=1,S7-AA7) -> FALSE | AC7: =IF(F7=1,VLOOKUP(C7,AWS1_30min!$C$3:$J$2747,8)) -> FALSE | AD7: =IF(F7=1,Const!$B$5*POWER((0+Const!$B$4),4)) -> FALSE | AE7: =IF(F7=1,AC7-AD7) -> FALSE | AF7: =IF(F7=1,AB7+AE7) -> FALSE | AG7: =VLOOKUP(C7,AWS2_30min!$C$3:$J$2935,8)+Const!$B$20*(L7-Const!$B$29) -> 18.9875 | AH7: =AG7+273.15 -> 292.1375 | AI7: =VLOOKUP(C7,AWS2_30min!$C$3:$K$2935,9) -> 30.97 | AJ7: =VLOOKUP(C7,AWS2_30min!$C$3:$L$2935,10) -> 1.9076345 | AK7: =IF(AJ7>0.5,Const!$B$6*(AH7-Const!$B$4)*(Const!$B$32-Const!$B$34)/(AH7*POWER(AJ7,2))) -> 0.35031332 | AL7: =IF(AK7<Const!$B$33,AK7,"ЛОЖЬ") -> 0.35031332 | AM7: =IF(AND(ISNUMBER(AL7),AL7>0),POWER((1-5*AL7),2),IF(ISNUMBER(AL7),POWER((1-16*AL7),0.75))) -> 0.56485239 | AN7: =(AG7+VLOOKUP(C7,AWS1_30min!$C$4:$L$2747,10))/2 -> 16.88525 | AO7: =VLOOKUP(C7,AWS1_30min!$C$4:$O$2747,13)/POWER(10,(L7-Const!$B$28)/18400*(1+0.003665*AN7)) -> 773.82725 | AP7: =Const!$B$7*Const!$B$8*(AO7/Const!$B$11)*POWER(Const!$B$9,2)*AJ7*(AH7-Const!$B$4)/(LN(Const!$B$32/Const!$B$34)*LN(Const!$B$32/Const!$B$35)) -> 76.14742 | AQ7: =IF(F7=1,AM7*AP7) -> FALSE | AR7: =AI7*((6.112*EXP(((17.62*AG7)/(243.12+AG7))))*(1.0016+0.0000315*AO7-0.074/AO7))/100 -> 6.9592761 | AS7: =0.623*Const!$B$10*Const!$B$8*POWER(Const!$B$9,2)*AJ7*(AR7-Const!$B$12)/1013/(LN(Const!$B$32/Const!$B$34)*LN(Const!$B$32/Const!$B$36)) -> 6.9325679 | AT7: =IF(F7=1,AM7*AS7) -> FALSE | AU7: =IF(F7=1,AQ7+AT7) -> FALSE | AV7: =VLOOKUP(C7,AWS1_30min!$C$4:$P$2747,14) -> 0 | AW7: =IF(AG7>=2,AV7/1000/1800) -> 0 | AX7: =IF(F7=1,AW7*Const!$B$13*Const!$B$14*(AH7-Const!$B$4)) -> FALSE | AY7: =IF(F7=1,-Const!$B$15*(Const!$B$4-Const!$B$31)/2) -> FALSE | AZ7: =IF(F7=1,AB7+AE7+AQ7+AT7+AY7+AX7) -> FALSE | BA7: =IF(V7=1,Const!$B$37,Const!$B$38) -> 784 | BB7: =IF(F7=1,AZ7/Const!$B$17*1800/BA7*1000) -> FALSE
A8: =A7 -> 43653 | B8: =B7 -> 0.5 | C8: =C7 -> 43653.5 | D8: =D7 -> 188 | E8: 5 | F8: 0 | G8: 0 | H8: 0 | J8: 524835 | K8: 6301125 | L8: 2346 | M8: 38.1859 | N8: 301.276 | O8: 1073.13 | P8: =VLOOKUP(C8,AWS2_30min!$C$3:$G$2935,5) -> 955.8 | Q8: =INDEX($O$4:$O$423,MATCH(1,$H$4:$H$423,0)) -> 856.334 | R8: =P8/Q8 -> 1.1161533 | S8: =IF(F8=1,R8*O8) -> FALSE | T8: =VLOOKUP(A8,Albedo!$A$2:$F$63,6) -> 0 | U8: =Const!$B$26*D8+Const!$B$27 -> 2402.4844 | V8: =IF(T8=1,1,IF(L8>=U8,1,0)) -> 0 | W8: =VLOOKUP(A8,Albedo!$A$2:$G$63,5)+Const!$B$20*(L8-Const!$B$29) -> 18.7145 | X8: =VLOOKUP(A8,Albedo!$A$2:$G$63,7) -> 3 | Y8: =IF(T8=1,W8,VLOOKUP(A8,Albedo!$A$2:$H$63,8)+(X8+1)*Const!$B$20*(L8-Const!$B$29)) -> 40.59 | Z8: =Const!$B$22*V8+Const!$B$23*W8+Const!$B$24*Y8+Const!$B$25 -> 0.24605671 | AA8: =IF(F8=1,S8*Z8) -> FALSE | AB8: =IF(F8=1,S8-AA8) -> FALSE | AC8: =IF(F8=1,VLOOKUP(C8,AWS1_30min!$C$3:$J$2747,8)) -> FALSE | AD8: =IF(F8=1,Const!$B$5*POWER((0+Const!$B$4),4)) -> FALSE | AE8: =IF(F8=1,AC8-AD8) -> FALSE | AF8: =IF(F8=1,AB8+AE8) -> FALSE | AG8: =VLOOKUP(C8,AWS2_30min!$C$3:$J$2935,8)+Const!$B$20*(L8-Const!$B$29) -> 18.7145 | AH8: =AG8+273.15 -> 291.8645 | AI8: =VLOOKUP(C8,AWS2_30min!$C$3:$K$2935,9) -> 30.97 | AJ8: =VLOOKUP(C8,AWS2_30min!$C$3:$L$2935,10) -> 1.9076345 | AK8: =IF(AJ8>0.5,Const!$B$6*(AH8-Const!$B$4)*(Const!$B$32-Const!$B$34)/(AH8*POWER(AJ8,2))) -> 0.34559952 | AL8: =IF(AK8<Const!$B$33,AK8,"ЛОЖЬ") -> 0.34559952 | AM8: =IF(AND(ISNUMBER(AL8),AL8>0),POWER((1-5*AL8),2),IF(ISNUMBER(AL8),POWER((1-16*AL8),0.75))) -> 0.52998051 | AN8: =(AG8+VLOOKUP(C8,AWS1_30min!$C$4:$L$2747,10))/2 -> 16.74875 | AO8: =VLOOKUP(C8,AWS1_30min!$C$4:$O$2747,13)/POWER(10,(L8-Const!$B$28)/18400*(1+0.003665*AN8)) -> 769.51161 | AP8: =Const!$B$7*Const!$B$8*(AO8/Const!$B$11)*POWER(Const!$B$9,2)*AJ8*(AH8-Const!$B$4)/(LN(Const!$B$32/Const!$B$34)*LN(Const!$B$32/Const!$B$35)) -> 74.634013 | AQ8: =IF(F8=1,AM8*AP8) -> FALSE | AR8: =AI8*((6.112*EXP(((17.62*AG8)/(243.12+AG8))))*(1.0016+0.0000315*AO8-0.074/AO8))/100 -> 6.8407809 | AS8: =0.623*Const!$B$10*Const!$B$8*POWER(Const!$B$9,2)*AJ8*(AR8-Const!$B$12)/1013/(LN(Const!$B$32/Const!$B$34)*LN(Const!$B$32/Const!$B$36)) -> 5.9653018 | AT8: =IF(F8=1,AM8*AS8) -> FALSE | AU8: =IF(F8=1,AQ8+AT8) -> FALSE | AV8: =VLOOKUP(C8,AWS1_30min!$C$4:$P$2747,14) -> 0 | AW8: =IF(AG8>=2,AV8/1000/1800) -> 0 | AX8: =IF(F8=1,AW8*Const!$B$13*Const!$B$14*(AH8-Const!$B$4)) -> FALSE | AY8: =IF(F8=1,-Const!$B$15*(Const!$B$4-Const!$B$31)/2) -> FALSE | AZ8: =IF(F8=1,AB8+AE8+AQ8+AT8+AY8+AX8) -> FALSE | BA8: =IF(V8=1,Const!$B$37,Const!$B$38) -> 784 | BB8: =IF(F8=1,AZ8/Const!$B$17*1800/BA8*1000) -> FALSE
A9: =A8 -> 43653 | B9: =B8 -> 0.5 | C9: =C8 -> 43653.5 | D9: =D8 -> 188 | E9: 6 | F9: 0 | G9: 0 | H9: 0 | J9: 524925 | K9: 6301125 | L9: 2414 | M9: 31.9666 | N9: 320.962 | O9: 1005.61 | P9: =VLOOKUP(C9,AWS2_30min!$C$3:$G$2935,5) -> 955.8 | Q9: =INDEX($O$4:$O$423,MATCH(1,$H$4:$H$423,0)) -> 856.334 | R9: =P9/Q9 -> 1.1161533 | S9: =IF(F9=1,R9*O9) -> FALSE | T9: =VLOOKUP(A9,Albedo!$A$2:$F$63,6) -> 0 | U9: =Const!$B$26*D9+Const!$B$27 -> 2402.4844 | V9: =IF(T9=1,1,IF(L9>=U9,1,0)) -> 1 | W9: =VLOOKUP(A9,Albedo!$A$2:$G$63,5)+Const!$B$20*(L9-Const!$B$29) -> 18.2725 | X9: =VLOOKUP(A9,Albedo!$A$2:$G$63,7) -> 3 | Y9: =IF(T9=1,W9,VLOOKUP(A9,Albedo!$A$2:$H$63,8)+(X9+1)*Const!$B$20*(L9-Const!$B$29)) -> 38.822 | Z9: =Const!$B$22*V9+Const!$B$23*W9+Const!$B$24*Y9+Const!$B$25 -> 0.58178291 | AA9: =IF(F9=1,S9*Z9) -> FALSE | AB9: =IF(F9=1,S9-AA9) -> FALSE | AC9: =IF(F9=1,VLOOKUP(C9,AWS1_30min!$C$3:$J$2747,8)) -> FALSE | AD9: =IF(F9=1,Const!$B$5*POWER((0+Const!$B$4),4)) -> FALSE | AE9: =IF(F9=1,AC9-AD9) -> FALSE | AF9: =IF(F9=1,AB9+AE9) -> FALSE | AG9: =VLOOKUP(C9,AWS2_30min!$C$3:$J$2935,8)+Const!$B$20*(L9-Const!$B$29) -> 18.2725 | AH9: =AG9+273.15 -> 291.4225 | AI9: =VLOOKUP(C9,AWS2_30min!$C$3:$K$2935,9) -> 30.97 | AJ9: =VLOOKUP(C9,AWS2_30min!$C$3:$L$2935,10) -> 1.9076345 | AK9: =IF(AJ9>0.5,Const!$B$6*(AH9-Const!$B$4)*(Const!$B$32-Const!$B$34)/(AH9*POWER(AJ9,2))) -> 0.33794892 | AL9: =IF(AK9<Const!$B$33,AK9,"ЛОЖЬ") -> 0.33794892 | AM9: =IF(AND(ISNUMBER(AL9),AL9>0),POWER((1-5*AL9),2),IF(ISNUMBER(AL9),POWER((1-16*AL9),0.75))) -> 0.47574765 | AN9: =(AG9+VLOOKUP(C9,AWS1_30min!$C$4:$L$2747,10))/2 -> 16.52775 | AO9: =VLOOKUP(C9,AWS1_30min!$C$4:$O$2747,13)/POWER(10,(L9-Const!$B$28)/18400*(1+0.003665*AN9)) -> 762.58386 | AP9: =Const!$B$7*Const!$B$8*(AO9/Const!$B$11)*POWER(Const!$B$9,2)*AJ9*(AH9-Const!$B$4)/(LN(Const!$B$32/Const!$B$34)*LN(Const!$B$32/Const!$B$35)) -> 72.215258 | AQ9: =IF(F9=1,AM9*AP9) -> FALSE | AR9: =AI9*((6.112*EXP(((17.62*AG9)/(243.12+AG9))))*(1.0016+0.0000315*AO9-0.074/AO9))/100 -> 6.652704 | AS9: =0.623*Const!$B$10*Const!$B$8*POWER(Const!$B$9,2)*AJ9*(AR9-Const!$B$12)/1013/(LN(Const!$B$32/Const!$B$34)*LN(Const!$B$32/Const!$B$36)) -> 4.430046 | AT9: =IF(F9=1,AM9*AS9) -> FALSE | AU9: =IF(F9=1,AQ9+AT9) -> FALSE | AV9: =VLOOKUP(C9,AWS1_30min!$C$4:$P$2747,14) -> 0 | AW9: =IF(AG9>=2,AV9/1000/1800) -> 0 | AX9: =IF(F9=1,AW9*Const!$B$13*Const!$B$14*(AH9-Const!$B$4)) -> FALSE | AY9: =IF(F9=1,-Const!$B$15*(Const!$B$4-Const!$B$31)/2) -> FALSE | AZ9: =IF(F9=1,AB9+AE9+AQ9+AT9+AY9+AX9) -> FALSE | BA9: =IF(V9=1,Const!$B$37,Const!$B$38) -> 602 | BB9: =IF(F9=1,AZ9/Const!$B$17*1800/BA9*1000) -> FALSE
A10: =A9 -> 43653 | B10: =B9 -> 0.5 | C10: =C9 -> 43653.5 | D10: =D9 -> 188 | E10: 7 | F10: 0 | G10: 0 | H10: 0 | J10: 525015 | K10: 6301125 | L10: 2414 | M10: 34.8327 | N10: 312.735 | O10: 1036.27 | P10: =VLOOKUP(C10,AWS2_30min!$C$3:$G$2935,5) -> 955.8 | Q10: =INDEX($O$4:$O$423,MATCH(1,$H$4:$H$423,0)) -> 856.334 | R10: =P10/Q10 -> 1.1161533 | S10: =IF(F10=1,R10*O10) -> FALSE | T10: =VLOOKUP(A10,Albedo!$A$2:$F$63,6) -> 0 | U10: =Const!$B$26*D10+Const!$B$27 -> 2402.4844 | V10: =IF(T10=1,1,IF(L10>=U10,1,0)) -> 1 | W10: =VLOOKUP(A10,Albedo!$A$2:$G$63,5)+Const!$B$20*(L10-Const!$B$29) -> 18.2725 | X10: =VLOOKUP(A10,Albedo!$A$2:$G$63,7) -> 3 | Y10: =IF(T10=1,W10,VLOOKUP(A10,Albedo!$A$2:$H$63,8)+(X10+1)*Const!$B$20*(L10-Const!$B$29)) -> 38.822 | Z10: =Const!$B$22*V10+Const!$B$23*W10+Const!$B$24*Y10+Const!$B$25 -> 0.58178291 | AA10: =IF(F10=1,S10*Z10) -> FALSE | AB10: =IF(F10=1,S10-AA10) -> FALSE | AC10: =IF(F10=1,VLOOKUP(C10,AWS1_30min!$C$3:$J$2747,8)) -> FALSE | AD10: =IF(F10=1,Const!$B$5*POWER((0+Const!$B$4),4)) -> FALSE | AE10: =IF(F10=1,AC10-AD10) -> FALSE | AF10: =IF(F10=1,AB10+AE10) -> FALSE | AG10: =VLOOKUP(C10,AWS2_30min!$C$3:$J$2935,8)+Const!$B$20*(L10-Const!$B$29) -> 18.2725 | AH10: =AG10+273.15 -> 291.4225 | AI10: =VLOOKUP(C10,AWS2_30min!$C$3:$K$2935,9) -> 30.97 | AJ10: =VLOOKUP(C10,AWS2_30min!$C$3:$L$2935,10) -> 1.9076345 | AK10: =IF(AJ10>0.5,Const!$B$6*(AH10-Const!$B$4)*(Const!$B$32-Const!$B$34)/(AH10*POWER(AJ10,2))) -> 0.33794892 | AL10: =IF(AK10<Const!$B$33,AK10,"ЛОЖЬ") -> 0.33794892 | AM10: =IF(AND(ISNUMBER(AL10),AL10>0),POWER((1-5*AL10),2),IF(ISNUMBER(AL10),POWER((1-16*AL10),0.75))) -> 0.47574765 | AN10: =(AG10+VLOOKUP(C10,AWS1_30min!$C$4:$L$2747,10))/2 -> 16.52775 | AO10: =VLOOKUP(C10,AWS1_30min!$C$4:$O$2747,13)/POWER(10,(L10-Const!$B$28)/18400*(1+0.003665*AN10)) -> 762.58386 | AP10: =Const!$B$7*Const!$B$8*(AO10/Const!$B$11)*POWER(Const!$B$9,2)*AJ10*(AH10-Const!$B$4)/(LN(Const!$B$32/Const!$B$34)*LN(Const!$B$32/Const!$B$35)) -> 72.215258 | AQ10: =IF(F10=1,AM10*AP10) -> FALSE | AR10: =AI10*((6.112*EXP(((17.62*AG10)/(243.12+AG10))))*(1.0016+0.0000315*AO10-0.074/AO10))/100 -> 6.652704 | AS10: =0.623*Const!$B$10*Const!$B$8*POWER(Const!$B$9,2)*AJ10*(AR10-Const!$B$12)/1013/(LN(Const!$B$32/Const!$B$34)*LN(Const!$B$32/Const!$B$36)) -> 4.430046 | AT10: =IF(F10=1,AM10*AS10) -> FALSE | AU10: =IF(F10=1,AQ10+AT10) -> FALSE | AV10: =VLOOKUP(C10,AWS1_30min!$C$4:$P$2747,14) -> 0 | AW10: =IF(AG10>=2,AV10/1000/1800) -> 0 | AX10: =IF(F10=1,AW10*Const!$B$13*Const!$B$14*(AH10-Const!$B$4)) -> FALSE | AY10: =IF(F10=1,-Const!$B$15*(Const!$B$4-Const!$B$31)/2) -> FALSE | AZ10: =IF(F10=1,AB10+AE10+AQ10+AT10+AY10+AX10) -> FALSE | BA10: =IF(V10=1,Const!$B$37,Const!$B$38) -> 602 | BB10: =IF(F10=1,AZ10/Const!$B$17*1800/BA10*1000) -> FALSE
A11: =A10 -> 43653 | B11: =B10 -> 0.5 | C11: =C10 -> 43653.5 | D11: =D10 -> 188 | E11: 8 | F11: 0 | G11: 0 | H11: 0 | J11: 525105 | K11: 6301125 | L11: 2511 | M11: 39.3313 | N11: 300.564 | O11: 1078.3 | P11: =VLOOKUP(C11,AWS2_30min!$C$3:$G$2935,5) -> 955.8 | Q11: =INDEX($O$4:$O$423,MATCH(1,$H$4:$H$423,0)) -> 856.334 | R11: =P11/Q11 -> 1.1161533 | S11: =IF(F11=1,R11*O11) -> FALSE | T11: =VLOOKUP(A11,Albedo!$A$2:$F$63,6) -> 0 | U11: =Const!$B$26*D11+Const!$B$27 -> 2402.4844 | V11: =IF(T11=1,1,IF(L11>=U11,1,0)) -> 1 | W11: =VLOOKUP(A11,Albedo!$A$2:$G$63,5)+Const!$B$20*(L11-Const!$B$29) -> 17.642 | X11: =VLOOKUP(A11,Albedo!$A$2:$G$63,7) -> 3 | Y11: =IF(T11=1,W11,VLOOKUP(A11,Albedo!$A$2:$H$63,8)+(X11+1)*Const!$B$20*(L11-Const!$B$29)) -> 36.3 | Z11: =Const!$B$22*V11+Const!$B$23*W11+Const!$B$24*Y11+Const!$B$25 -> 0.57932396 | AA11: =IF(F11=1,S11*Z11) -> FALSE | AB11: =IF(F11=1,S11-AA11) -> FALSE | AC11: =IF(F11=1,VLOOKUP(C11,AWS1_30min!$C$3:$J$2747,8)) -> FALSE | AD11: =IF(F11=1,Const!$B$5*POWER((0+Const!$B$4),4)) -> FALSE | AE11: =IF(F11=1,AC11-AD11) -> FALSE | AF11: =IF(F11=1,AB11+AE11) -> FALSE | AG11: =VLOOKUP(C11,AWS2_30min!$C$3:$J$2935,8)+Const!$B$20*(L11-Const!$B$29) -> 17.642 | AH11: =AG11+273.15 -> 290.792 | AI11: =VLOOKUP(C11,AWS2_30min!$C$3:$K$2935,9) -> 30.97 | AJ11: =VLOOKUP(C11,AWS2_30min!$C$3:$L$2935,10) -> 1.9076345 | AK11: =IF(AJ11>0.5,Const!$B$6*(AH11-Const!$B$4)*(Const!$B$32-Const!$B$34)/(AH11*POWER(AJ11,2))) -> 0.32699532 | AL11: =IF(AK11<Const!$B$33,AK11,"ЛОЖЬ") -> 0.32699532 | AM11: =IF(AND(ISNUMBER(AL11),AL11>0),POWER((1-5*AL11),2),IF(ISNUMBER(AL11),POWER((1-16*AL11),0.75))) -> 0.4031953 | AN11: =(AG11+VLOOKUP(C11,AWS1_30min!$C$4:$L$2747,10))/2 -> 16.2125 | AO11: =VLOOKUP(C11,AWS1_30min!$C$4:$O$2747,13)/POWER(10,(L11-Const!$B$28)/18400*(1+0.003665*AN11)) -> 752.82738 | AP11: =Const!$B$7*Const!$B$8*(AO11/Const!$B$11)*POWER(Const!$B$9,2)*AJ11*(AH11-Const!$B$4)/(LN(Const!$B$32/Const!$B$34)*LN(Const!$B$32/Const!$B$35)) -> 68.831402 | AQ11: =IF(F11=1,AM11*AP11) -> FALSE | AR11: =AI11*((6.112*EXP(((17.62*AG11)/(243.12+AG11))))*(1.0016+0.0000315*AO11-0.074/AO11))/100 -> 6.3923181 | AS11: =0.623*Const!$B$10*Const!$B$8*POWER(Const!$B$9,2)*AJ11*(AR11-Const!$B$12)/1013/(LN(Const!$B$32/Const!$B$34)*LN(Const!$B$32/Const!$B$36)) -> 2.3045388 | AT11: =IF(F11=1,AM11*AS11) -> FALSE | AU11: =IF(F11=1,AQ11+AT11) -> FALSE | AV11: =VLOOKUP(C11,AWS1_30min!$C$4:$P$2747,14) -> 0 | AW11: =IF(AG11>=2,AV11/1000/1800) -> 0 | AX11: =IF(F11=1,AW11*Const!$B$13*Const!$B$14*(AH11-Const!$B$4)) -> FALSE | AY11: =IF(F11=1,-Const!$B$15*(Const!$B$4-Const!$B$31)/2) -> FALSE | AZ11: =IF(F11=1,AB11+AE11+AQ11+AT11+AY11+AX11) -> FALSE | BA11: =IF(V11=1,Const!$B$37,Const!$B$38) -> 602 | BB11: =IF(F11=1,AZ11/Const!$B$17*1800/BA11*1000) -> FALSE
A12: =A11 -> 43653 | B12: =B11 -> 0.5 | C12: =C11 -> 43653.5 | D12: =D11 -> 188 | E12: 9 | F12: 0 | G12: 0 | H12: 0 | J12: 525195 | K12: 6301125 | L12: 2581 | M12: 43.419 | N12: 287.158 | O12: 1110.5 | P12: =VLOOKUP(C12,AWS2_30min!$C$3:$G$2935,5) -> 955.8 | Q12: =INDEX($O$4:$O$423,MATCH(1,$H$4:$H$423,0)) -> 856.334 | R12: =P12/Q12 -> 1.1161533 | S12: =IF(F12=1,R12*O12) -> FALSE | T12: =VLOOKUP(A12,Albedo!$A$2:$F$63,6) -> 0 | U12: =Const!$B$26*D12+Const!$B$27 -> 2402.4844 | V12: =IF(T12=1,1,IF(L12>=U12,1,0)) -> 1 | W12: =VLOOKUP(A12,Albedo!$A$2:$G$63,5)+Const!$B$20*(L12-Const!$B$29) -> 17.187 | X12: =VLOOKUP(A12,Albedo!$A$2:$G$63,7) -> 3 | Y12: =IF(T12=1,W12,VLOOKUP(A12,Albedo!$A$2:$H$63,8)+(X12+1)*Const!$B$20*(L12-Const!$B$29)) -> 34.48 | Z12: =Const!$B$22*V12+Const!$B$23*W12+Const!$B$24*Y12+Const!$B$25 -> 0.57754946 | AA12: =IF(F12=1,S12*Z12) -> FALSE | AB12: =IF(F12=1,S12-AA12) -> FALSE | AC12: =IF(F12=1,VLOOKUP(C12,AWS1_30min!$C$3:$J$2747,8)) -> FALSE | AD12: =IF(F12=1,Const!$B$5*POWER((0+Const!$B$4),4)) -> FALSE | AE12: =IF(F12=1,AC12-AD12) -> FALSE | AF12: =IF(F12=1,AB12+AE12) -> FALSE | AG12: =VLOOKUP(C12,AWS2_30min!$C$3:$J$2935,8)+Const!$B$20*(L12-Const!$B$29) -> 17.187 | AH12: =AG12+273.15 -> 290.337 | AI12: =VLOOKUP(C12,AWS2_30min!$C$3:$K$2935,9) -> 30.97 | AJ12: =VLOOKUP(C12,AWS2_30min!$C$3:$L$2935,10) -> 1.9076345 | AK12: =IF(AJ12>0.5,Const!$B$6*(AH12-Const!$B$4)*(Const!$B$32-Const!$B$34)/(AH12*POWER(AJ12,2))) -> 0.31906111 | AL12: =IF(AK12<Const!$B$33,AK12,"ЛОЖЬ") -> 0.31906111 | AM12: =IF(AND(ISNUMBER(AL12),AL12>0),POWER((1-5*AL12),2),IF(ISNUMBER(AL12),POWER((1-16*AL12),0.75))) -> 0.35438869 | AN12: =(AG12+VLOOKUP(C12,AWS1_30min!$C$4:$L$2747,10))/2 -> 15.985 | AO12: =VLOOKUP(C12,AWS1_30min!$C$4:$O$2747,13)/POWER(10,(L12-Const!$B$28)/18400*(1+0.003665*AN12)) -> 745.87726 | AP12: =Const!$B$7*Const!$B$8*(AO12/Const!$B$11)*POWER(Const!$B$9,2)*AJ12*(AH12-Const!$B$4)/(LN(Const!$B$32/Const!$B$34)*LN(Const!$B$32/Const!$B$35)) -> 66.437125 | AQ12: =IF(F12=1,AM12*AP12) -> FALSE | AR12: =AI12*((6.112*EXP(((17.62*AG12)/(243.12+AG12))))*(1.0016+0.0000315*AO12-0.074/AO12))/100 -> 6.2100415 | AS12: =0.623*Const!$B$10*Const!$B$8*POWER(Const!$B$9,2)*AJ12*(AR12-Const!$B$12)/1013/(LN(Const!$B$32/Const!$B$34)*LN(Const!$B$32/Const!$B$36)) -> 0.81663046 | AT12: =IF(F12=1,AM12*AS12) -> FALSE | AU12: =IF(F12=1,AQ12+AT12) -> FALSE | AV12: =VLOOKUP(C12,AWS1_30min!$C$4:$P$2747,14) -> 0 | AW12: =IF(AG12>=2,AV12/1000/1800) -> 0 | AX12: =IF(F12=1,AW12*Const!$B$13*Const!$B$14*(AH12-Const!$B$4)) -> FALSE | AY12: =IF(F12=1,-Const!$B$15*(Const!$B$4-Const!$B$31)/2) -> FALSE | AZ12: =IF(F12=1,AB12+AE12+AQ12+AT12+AY12+AX12) -> FALSE | BA12: =IF(V12=1,Const!$B$37,Const!$B$38) -> 602 | BB12: =IF(F12=1,AZ12/Const!$B$17*1800/BA12*1000) -> FALSE
A13: =A12 -> 43653 | B13: =B12 -> 0.5 | C13: =C12 -> 43653.5 | D13: =D12 -> 188 | E13: 10 | F13: 0 | G13: 0 | H13: 0 | J13: 525285 | K13: 6301125 | L13: 2689 | M13: 38.2697 | N13: 270.202 | O13: 1137.67 | P13: =VLOOKUP(C13,AWS2_30min!$C$3:$G$2935,5) -> 955.8 | Q13: =INDEX($O$4:$O$423,MATCH(1,$H$4:$H$423,0)) -> 856.334 | R13: =P13/Q13 -> 1.1161533 | S13: =IF(F13=1,R13*O13) -> FALSE | T13: =VLOOKUP(A13,Albedo!$A$2:$F$63,6) -> 0 | U13: =Const!$B$26*D13+Const!$B$27 -> 2402.4844 | V13: =IF(T13=1,1,IF(L13>=U13,1,0)) -> 1 | W13: =VLOOKUP(A13,Albedo!$A$2:$G$63,5)+Const!$B$20*(L13-Const!$B$29) -> 16.485 | X13: =VLOOKUP(A13,Albedo!$A$2:$G$63,7) -> 3 | Y13: =IF(T13=1,W13,VLOOKUP(A13,Albedo!$A$2:$H$63,8)+(X13+1)*Const!$B$20*(L13-Const!$B$29)) -> 31.672 | Z13: =Const!$B$22*V13+Const!$B$23*W13+Const!$B$24*Y13+Const!$B$25 -> 0.57481166 | AA13: =IF(F13=1,S13*Z13) -> FALSE | AB13: =IF(F13=1,S13-AA13) -> FALSE | AC13: =IF(F13=1,VLOOKUP(C13,AWS1_30min!$C$3:$J$2747,8)) -> FALSE | AD13: =IF(F13=1,Const!$B$5*POWER((0+Const!$B$4),4)) -> FALSE | AE13: =IF(F13=1,AC13-AD13) -> FALSE | AF13: =IF(F13=1,AB13+AE13) -> FALSE | AG13: =VLOOKUP(C13,AWS2_30min!$C$3:$J$2935,8)+Const!$B$20*(L13-Const!$B$29) -> 16.485 | AH13: =AG13+273.15 -> 289.635 | AI13: =VLOOKUP(C13,AWS2_30min!$C$3:$K$2935,9) -> 30.97 | AJ13: =VLOOKUP(C13,AWS2_30min!$C$3:$L$2935,10) -> 1.9076345 | AK13: =IF(AJ13>0.5,Const!$B$6*(AH13-Const!$B$4)*(Const!$B$32-Const!$B$34)/(AH13*POWER(AJ13,2))) -> 0.30677085 | AL13: =IF(AK13<Const!$B$33,AK13,"ЛОЖЬ") -> 0.30677085 | AM13: =IF(AND(ISNUMBER(AL13),AL13>0),POWER((1-5*AL13),2),IF(ISNUMBER(AL13),POWER((1-16*AL13),0.75))) -> 0.28500035 | AN13: =(AG13+VLOOKUP(C13,AWS1_30min!$C$4:$L$2747,10))/2 -> 15.634 | AO13: =VLOOKUP(C13,AWS1_30min!$C$4:$O$2747,13)/POWER(10,(L13-Const!$B$28)/18400*(1+0.003665*AN13)) -> 735.30094 | AP13: =Const!$B$7*Const!$B$8*(AO13/Const!$B$11)*POWER(Const!$B$9,2)*AJ13*(AH13-Const!$B$4)/(LN(Const!$B$32/Const!$B$34)*LN(Const!$B$32/Const!$B$35)) -> 62.819932 | AQ13: =IF(F13=1,AM13*AP13) -> FALSE | AR13: =AI13*((6.112*EXP(((17.62*AG13)/(243.12+AG13))))*(1.0016+0.0000315*AO13-0.074/AO13))/100 -> 5.9378114 | AS13: =0.623*Const!$B$10*Const!$B$8*POWER(Const!$B$9,2)*AJ13*(AR13-Const!$B$12)/1013/(LN(Const!$B$32/Const!$B$34)*LN(Const!$B$32/Const!$B$36)) -> -1.4055606 | AT13: =IF(F13=1,AM13*AS13) -> FALSE | AU13: =IF(F13=1,AQ13+AT13) -> FALSE | AV13: =VLOOKUP(C13,AWS1_30min!$C$4:$P$2747,14) -> 0 | AW13: =IF(AG13>=2,AV13/1000/1800) -> 0 | AX13: =IF(F13=1,AW13*Const!$B$13*Const!$B$14*(AH13-Const!$B$4)) -> FALSE | AY13: =IF(F13=1,-Const!$B$15*(Const!$B$4-Const!$B$31)/2) -> FALSE | AZ13: =IF(F13=1,AB13+AE13+AQ13+AT13+AY13+AX13) -> FALSE | BA13: =IF(V13=1,Const!$B$37,Const!$B$38) -> 602 | BB13: =IF(F13=1,AZ13/Const!$B$17*1800/BA13*1000) -> FALSE
A14: =A13 -> 43653 | B14: =B13 -> 0.5 | C14: =C13 -> 43653.5 | D14: =D13 -> 188 | E14: 11 | F14: 0 | G14: 0 | H14: 0 | J14: 525375 | K14: 6301125 | L14: 2693 | M14: 12.313 | N14: 150.662 | O14: 845.792 | P14: =VLOOKUP(C14,AWS2_30min!$C$3:$G$2935,5) -> 955.8 | Q14: =INDEX($O$4:$O$423,MATCH(1,$H$4:$H$423,0)) -> 856.334 | R14: =P14/Q14 -> 1.1161533 | S14: =IF(F14=1,R14*O14) -> FALSE | T14: =VLOOKUP(A14,Albedo!$A$2:$F$63,6) -> 0 | U14: =Const!$B$26*D14+Const!$B$27 -> 2402.4844 | V14: =IF(T14=1,1,IF(L14>=U14,1,0)) -> 1 | W14: =VLOOKUP(A14,Albedo!$A$2:$G$63,5)+Const!$B$20*(L14-Const!$B$29) -> 16.459 | X14: =VLOOKUP(A14,Albedo!$A$2:$G$63,7) -> 3 | Y14: =IF(T14=1,W14,VLOOKUP(A14,Albedo!$A$2:$H$63,8)+(X14+1)*Const!$B$20*(L14-Const!$B$29)) -> 31.568 | Z14: =Const!$B$22*V14+Const!$B$23*W14+Const!$B$24*Y14+Const!$B$25 -> 0.57471026 | AA14: =IF(F14=1,S14*Z14) -> FALSE | AB14: =IF(F14=1,S14-AA14) -> FALSE | AC14: =IF(F14=1,VLOOKUP(C14,AWS1_30min!$C$3:$J$2747,8)) -> FALSE | AD14: =IF(F14=1,Const!$B$5*POWER((0+Const!$B$4),4)) -> FALSE | AE14: =IF(F14=1,AC14-AD14) -> FALSE | AF14: =IF(F14=1,AB14+AE14) -> FALSE | AG14: =VLOOKUP(C14,AWS2_30min!$C$3:$J$2935,8)+Const!$B$20*(L14-Const!$B$29) -> 16.459 | AH14: =AG14+273.15 -> 289.609 | AI14: =VLOOKUP(C14,AWS2_30min!$C$3:$K$2935,9) -> 30.97 | AJ14: =VLOOKUP(C14,AWS2_30min!$C$3:$L$2935,10) -> 1.9076345 | AK14: =IF(AJ14>0.5,Const!$B$6*(AH14-Const!$B$4)*(Const!$B$32-Const!$B$34)/(AH14*POWER(AJ14,2))) -> 0.30631451 | AL14: =IF(AK14<Const!$B$33,AK14,"ЛОЖЬ") -> 0.30631451 | AM14: =IF(AND(ISNUMBER(AL14),AL14>0),POWER((1-5*AL14),2),IF(ISNUMBER(AL14),POWER((1-16*AL14),0.75))) -> 0.28256937 | AN14: =(AG14+VLOOKUP(C14,AWS1_30min!$C$4:$L$2747,10))/2 -> 15.621 | AO14: =VLOOKUP(C14,AWS1_30min!$C$4:$O$2747,13)/POWER(10,(L14-Const!$B$28)/18400*(1+0.003665*AN14)) -> 734.9126 | AP14: =Const!$B$7*Const!$B$8*(AO14/Const!$B$11)*POWER(Const!$B$9,2)*AJ14*(AH14-Const!$B$4)/(LN(Const!$B$32/Const!$B$34)*LN(Const!$B$32/Const!$B$35)) -> 62.687728 | AQ14: =IF(F14=1,AM14*AP14) -> FALSE | AR14: =AI14*((6.112*EXP(((17.62*AG14)/(243.12+AG14))))*(1.0016+0.0000315*AO14-0.074/AO14))/100 -> 5.9279345 | AS14: =0.623*Const!$B$10*Const!$B$8*POWER(Const!$B$9,2)*AJ14*(AR14-Const!$B$12)/1013/(LN(Const!$B$32/Const!$B$34)*LN(Const!$B$32/Const!$B$36)) -> -1.486185 | AT14: =IF(F14=1,AM14*AS14) -> FALSE | AU14: =IF(F14=1,AQ14+AT14) -> FALSE | AV14: =VLOOKUP(C14,AWS1_30min!$C$4:$P$2747,14) -> 0 | AW14: =IF(AG14>=2,AV14/1000/1800) -> 0 | AX14: =IF(F14=1,AW14*Const!$B$13*Const!$B$14*(AH14-Const!$B$4)) -> FALSE | AY14: =IF(F14=1,-Const!$B$15*(Const!$B$4-Const!$B$31)/2) -> FALSE | AZ14: =IF(F14=1,AB14+AE14+AQ14+AT14+AY14+AX14) -> FALSE | BA14: =IF(V14=1,Const!$B$37,Const!$B$38) -> 602 | BB14: =IF(F14=1,AZ14/Const!$B$17*1800/BA14*1000) -> FALSE
A15: =A14 -> 43653 | B15: =B14 -> 0.5 | C15: =C14 -> 43653.5 | D15: =D14 -> 188 | E15: 12 | F15: 0 | G15: 0 | H15: 0 | J15: 525465 | K15: 6301125 | L15: 2665 | M15: 14.7459 | N15: 135 | O15: 791.011 | P15: =VLOOKUP(C15,AWS2_30min!$C$3:$G$2935,5) -> 955.8 | Q15: =INDEX($O$4:$O$423,MATCH(1,$H$4:$H$423,0)) -> 856.334 | R15: =P15/Q15 -> 1.1161533 | S15: =IF(F15=1,R15*O15) -> FALSE | T15: =VLOOKUP(A15,Albedo!$A$2:$F$63,6) -> 0 | U15: =Const!$B$26*D15+Const!$B$27 -> 2402.4844 | V15: =IF(T15=1,1,IF(L15>=U15,1,0)) -> 1 | W15: =VLOOKUP(A15,Albedo!$A$2:$G$63,5)+Const!$B$20*(L15-Const!$B$29) -> 16.641 | X15: =VLOOKUP(A15,Albedo!$A$2:$G$63,7) -> 3 | Y15: =IF(T15=1,W15,VLOOKUP(A15,Albedo!$A$2:$H$63,8)+(X15+1)*Const!$B$20*(L15-Const!$B$29)) -> 32.296 | Z15: =Const!$B$22*V15+Const!$B$23*W15+Const!$B$24*Y15+Const!$B$25 -> 0.57542006 | AA15: =IF(F15=1,S15*Z15) -> FALSE | AB15: =IF(F15=1,S15-AA15) -> FALSE | AC15: =IF(F15=1,VLOOKUP(C15,AWS1_30min!$C$3:$J$2747,8)) -> FALSE | AD15: =IF(F15=1,Const!$B$5*POWER((0+Const!$B$4),4)) -> FALSE | AE15: =IF(F15=1,AC15-AD15) -> FALSE | AF15: =IF(F15=1,AB15+AE15) -> FALSE | AG15: =VLOOKUP(C15,AWS2_30min!$C$3:$J$2935,8)+Const!$B$20*(L15-Const!$B$29) -> 16.641 | AH15: =AG15+273.15 -> 289.791 | AI15: =VLOOKUP(C15,AWS2_30min!$C$3:$K$2935,9) -> 30.97 | AJ15: =VLOOKUP(C15,AWS2_30min!$C$3:$L$2935,10) -> 1.9076345 | AK15: =IF(AJ15>0.5,Const!$B$6*(AH15-Const!$B$4)*(Const!$B$32-Const!$B$34)/(AH15*POWER(AJ15,2))) -> 0.30950716 | AL15: =IF(AK15<Const!$B$33,AK15,"ЛОЖЬ") -> 0.30950716 | AM15: =IF(AND(ISNUMBER(AL15),AL15>0),POWER((1-5*AL15),2),IF(ISNUMBER(AL15),POWER((1-16*AL15),0.75))) -> 0.29979547 | AN15: =(AG15+VLOOKUP(C15,AWS1_30min!$C$4:$L$2747,10))/2 -> 15.712 | AO15: =VLOOKUP(C15,AWS1_30min!$C$4:$O$2747,13)/POWER(10,(L15-Const!$B$28)/18400*(1+0.003665*AN15)) -> 737.63598 | AP15: =Const!$B$7*Const!$B$8*(AO15/Const!$B$11)*POWER(Const!$B$9,2)*AJ15*(AH15-Const!$B$4)/(LN(Const!$B$32/Const!$B$34)*LN(Const!$B$32/Const!$B$35)) -> 63.615786 | AQ15: =IF(F15=1,AM15*AP15) -> FALSE | AR15: =AI15*((6.112*EXP(((17.62*AG15)/(243.12+AG15))))*(1.0016+0.0000315*AO15-0.074/AO15))/100 -> 5.9973787 | AS15: =0.623*Const!$B$10*Const!$B$8*POWER(Const!$B$9,2)*AJ15*(AR15-Const!$B$12)/1013/(LN(Const!$B$32/Const!$B$34)*LN(Const!$B$32/Const!$B$36)) -> -0.91931785 | AT15: =IF(F15=1,AM15*AS15) -> FALSE | AU15: =IF(F15=1,AQ15+AT15) -> FALSE | AV15: =VLOOKUP(C15,AWS1_30min!$C$4:$P$2747,14) -> 0 | AW15: =IF(AG15>=2,AV15/1000/1800) -> 0 | AX15: =IF(F15=1,AW15*Const!$B$13*Const!$B$14*(AH15-Const!$B$4)) -> FALSE | AY15: =IF(F15=1,-Const!$B$15*(Const!$B$4-Const!$B$31)/2) -> FALSE | AZ15: =IF(F15=1,AB15+AE15+AQ15+AT15+AY15+AX15) -> FALSE | BA15: =IF(V15=1,Const!$B$37,Const!$B$38) -> 602 | BB15: =IF(F15=1,AZ15/Const!$B$17*1800/BA15*1000) -> FALSE
A16: =A15 -> 43653 | B16: =B15 -> 0.5 | C16: =C15 -> 43653.5 | D16: =D15 -> 188 | E16: 13 | F16: 0 | G16: 0 | H16: 0 | J16: 525555 | K16: 6301125 | L16: 2665 | M16: 17.2192 | N16: 104.534 | O16: 716.172 | P16: =VLOOKUP(C16,AWS2_30min!$C$3:$G$2935,5) -> 955.8 | Q16: =INDEX($O$4:$O$423,MATCH(1,$H$4:$H$423,0)) -> 856.334 | R16: =P16/Q16 -> 1.1161533 | S16: =IF(F16=1,R16*O16) -> FALSE | T16: =VLOOKUP(A16,Albedo!$A$2:$F$63,6) -> 0 | U16: =Const!$B$26*D16+Const!$B$27 -> 2402.4844 | V16: =IF(T16=1,1,IF(L16>=U16,1,0)) -> 1 | W16: =VLOOKUP(A16,Albedo!$A$2:$G$63,5)+Const!$B$20*(L16-Const!$B$29) -> 16.641 | X16: =VLOOKUP(A16,Albedo!$A$2:$G$63,7) -> 3 | Y16: =IF(T16=1,W16,VLOOKUP(A16,Albedo!$A$2:$H$63,8)+(X16+1)*Const!$B$20*(L16-Const!$B$29)) -> 32.296 | Z16: =Const!$B$22*V16+Const!$B$23*W16+Const!$B$24*Y16+Const!$B$25 -> 0.57542006 | AA16: =IF(F16=1,S16*Z16) -> FALSE | AB16: =IF(F16=1,S16-AA16) -> FALSE | AC16: =IF(F16=1,VLOOKUP(C16,AWS1_30min!$C$3:$J$2747,8)) -> FALSE | AD16: =IF(F16=1,Const!$B$5*POWER((0+Const!$B$4),4)) -> FALSE | AE16: =IF(F16=1,AC16-AD16) -> FALSE | AF16: =IF(F16=1,AB16+AE16) -> FALSE | AG16: =VLOOKUP(C16,AWS2_30min!$C$3:$J$2935,8)+Const!$B$20*(L16-Const!$B$29) -> 16.641 | AH16: =AG16+273.15 -> 289.791 | AI16: =VLOOKUP(C16,AWS2_30min!$C$3:$K$2935,9) -> 30.97 | AJ16: =VLOOKUP(C16,AWS2_30min!$C$3:$L$2935,10) -> 1.9076345 | AK16: =IF(AJ16>0.5,Const!$B$6*(AH16-Const!$B$4)*(Const!$B$32-Const!$B$34)/(AH16*POWER(AJ16,2))) -> 0.30950716 | AL16: =IF(AK16<Const!$B$33,AK16,"ЛОЖЬ") -> 0.30950716 | AM16: =IF(AND(ISNUMBER(AL16),AL16>0),POWER((1-5*AL16),2),IF(ISNUMBER(AL16),POWER((1-16*AL16),0.75))) -> 0.29979547 | AN16: =(AG16+VLOOKUP(C16,AWS1_30min!$C$4:$L$2747,10))/2 -> 15.712 | AO16: =VLOOKUP(C16,AWS1_30min!$C$4:$O$2747,13)/POWER(10,(L16-Const!$B$28)/18400*(1+0.003665*AN16)) -> 737.63598 | AP16: =Const!$B$7*Const!$B$8*(AO16/Const!$B$11)*POWER(Const!$B$9,2)*AJ16*(AH16-Const!$B$4)/(LN(Const!$B$32/Const!$B$34)*LN(Const!$B$32/Const!$B$35)) -> 63.615786 | AQ16: =IF(F16=1,AM16*AP16) -> FALSE | AR16: =AI16*((6.112*EXP(((17.62*AG16)/(243.12+AG16))))*(1.0016+0.0000315*AO16-0.074/AO16))/100 -> 5.9973787 | AS16: =0.623*Const!$B$10*Const!$B$8*POWER(Const!$B$9,2)*AJ16*(AR16-Const!$B$12)/1013/(LN(Const!$B$32/Const!$B$34)*LN(Const!$B$32/Const!$B$36)) -> -0.91931785 | AT16: =IF(F16=1,AM16*AS16) -> FALSE | AU16: =IF(F16=1,AQ16+AT16) -> FALSE | AV16: =VLOOKUP(C16,AWS1_30min!$C$4:$P$2747,14) -> 0 | AW16: =IF(AG16>=2,AV16/1000/1800) -> 0 | AX16: =IF(F16=1,AW16*Const!$B$13*Const!$B$14*(AH16-Const!$B$4)) -> FALSE | AY16: =IF(F16=1,-Const!$B$15*(Const!$B$4-Const!$B$31)/2) -> FALSE | AZ16: =IF(F16=1,AB16+AE16+AQ16+AT16+AY16+AX16) -> FALSE | BA16: =IF(V16=1,Const!$B$37,Const!$B$38) -> 602 | BB16: =IF(F16=1,AZ16/Const!$B$17*1800/BA16*1000) -> FALSE
